----------------------------------------
Exception occurred during processing of request from ('127.0.0.1', 58839)
Traceback (most recent call last):
  File "/Users/facundorios/Documents/Facundo/Programacion/Proyectos/Proyecto Messi/proxy_server.py", line 159, in update_stats
    self.wfile.write(json.dumps(response, ensure_ascii=False).encode())
  File "/Library/Developer/CommandLineTools/Library/Frameworks/Python3.framework/Versions/3.9/lib/python3.9/socketserver.py", line 826, in write
    self._sock.sendall(b)
BrokenPipeError: [Errno 32] Broken pipe

During handling of the above exception, another exception occurred:

Traceback (most recent call last):
  File "/Library/Developer/CommandLineTools/Library/Frameworks/Python3.framework/Versions/3.9/lib/python3.9/socketserver.py", line 316, in _handle_request_noblock
    self.process_request(request, client_address)
  File "/Library/Developer/CommandLineTools/Library/Frameworks/Python3.framework/Versions/3.9/lib/python3.9/socketserver.py", line 347, in process_request
    self.finish_request(request, client_address)
  File "/Library/Developer/CommandLineTools/Library/Frameworks/Python3.framework/Versions/3.9/lib/python3.9/socketserver.py", line 360, in finish_request
    self.RequestHandlerClass(request, client_address, self)
  File "/Library/Developer/CommandLineTools/Library/Frameworks/Python3.framework/Versions/3.9/lib/python3.9/socketserver.py", line 747, in __init__
    self.handle()
  File "/Library/Developer/CommandLineTools/Library/Frameworks/Python3.framework/Versions/3.9/lib/python3.9/http/server.py", line 434, in handle
    self.handle_one_request()
  File "/Library/Developer/CommandLineTools/Library/Frameworks/Python3.framework/Versions/3.9/lib/python3.9/http/server.py", line 422, in handle_one_request
    method()
  File "/Users/facundorios/Documents/Facundo/Programacion/Proyectos/Proyecto Messi/proxy_server.py", line 23, in do_GET
    self.update_stats()
  File "/Users/facundorios/Documents/Facundo/Programacion/Proyectos/Proyecto Messi/proxy_server.py", line 162, in update_stats
    self.send_error(500, f"Error en actualización: {str(e)}")
  File "/Library/Developer/CommandLineTools/Library/Frameworks/Python3.framework/Versions/3.9/lib/python3.9/http/server.py", line 486, in send_error
    self.end_headers()
  File "/Library/Developer/CommandLineTools/Library/Frameworks/Python3.framework/Versions/3.9/lib/python3.9/http/server.py", line 536, in end_headers
    self.flush_headers()
  File "/Library/Developer/CommandLineTools/Library/Frameworks/Python3.framework/Versions/3.9/lib/python3.9/http/server.py", line 540, in flush_headers
    self.wfile.write(b"".join(self._headers_buffer))
  File "/Library/Developer/CommandLineTools/Library/Frameworks/Python3.framework/Versions/3.9/lib/python3.9/socketserver.py", line 826, in write
    self._sock.sendall(b)
BrokenPipeError: [Errno 32] Broken pipe
----------------------------------------
----------------------------------------
Exception occurred during processing of request from ('127.0.0.1', 58846)
Traceback (most recent call last):
  File "/Users/facundorios/Documents/Facundo/Programacion/Proyectos/Proyecto Messi/proxy_server.py", line 129, in serve_messi_stats
    self.wfile.write(json.dumps(stats, ensure_ascii=False).encode())
  File "/Library/Developer/CommandLineTools/Library/Frameworks/Python3.framework/Versions/3.9/lib/python3.9/socketserver.py", line 826, in write
    self._sock.sendall(b)
BrokenPipeError: [Errno 32] Broken pipe

During handling of the above exception, another exception occurred:

Traceback (most recent call last):
  File "/Library/Developer/CommandLineTools/Library/Frameworks/Python3.framework/Versions/3.9/lib/python3.9/socketserver.py", line 316, in _handle_request_noblock
    self.process_request(request, client_address)
  File "/Library/Developer/CommandLineTools/Library/Frameworks/Python3.framework/Versions/3.9/lib/python3.9/socketserver.py", line 347, in process_request
    self.finish_request(request, client_address)
  File "/Library/Developer/CommandLineTools/Library/Frameworks/Python3.framework/Versions/3.9/lib/python3.9/socketserver.py", line 360, in finish_request
    self.RequestHandlerClass(request, client_address, self)
  File "/Library/Developer/CommandLineTools/Library/Frameworks/Python3.framework/Versions/3.9/lib/python3.9/socketserver.py", line 747, in __init__
    self.handle()
  File "/Library/Developer/CommandLineTools/Library/Frameworks/Python3.framework/Versions/3.9/lib/python3.9/http/server.py", line 434, in handle
    self.handle_one_request()
  File "/Library/Developer/CommandLineTools/Library/Frameworks/Python3.framework/Versions/3.9/lib/python3.9/http/server.py", line 422, in handle_one_request
    method()
  File "/Users/facundorios/Documents/Facundo/Programacion/Proyectos/Proyecto Messi/proxy_server.py", line 21, in do_GET
    self.serve_messi_stats()
  File "/Users/facundorios/Documents/Facundo/Programacion/Proyectos/Proyecto Messi/proxy_server.py", line 132, in serve_messi_stats
    self.send_error(500, f"Error al leer estadísticas: {str(e)}")
  File "/Library/Developer/CommandLineTools/Library/Frameworks/Python3.framework/Versions/3.9/lib/python3.9/http/server.py", line 486, in send_error
    self.end_headers()
  File "/Library/Developer/CommandLineTools/Library/Frameworks/Python3.framework/Versions/3.9/lib/python3.9/http/server.py", line 536, in end_headers
    self.flush_headers()
  File "/Library/Developer/CommandLineTools/Library/Frameworks/Python3.framework/Versions/3.9/lib/python3.9/http/server.py", line 540, in flush_headers
    self.wfile.write(b"".join(self._headers_buffer))
  File "/Library/Developer/CommandLineTools/Library/Frameworks/Python3.framework/Versions/3.9/lib/python3.9/socketserver.py", line 826, in write
    self._sock.sendall(b)
BrokenPipeError: [Errno 32] Broken pipe
----------------------------------------
----------------------------------------
Exception occurred during processing of request from ('127.0.0.1', 60653)
Traceback (most recent call last):
  File "/Users/facundorios/Documents/Facundo/Programacion/Proyectos/Proyecto Messi/proxy_server.py", line 159, in update_stats
    self.wfile.write(json.dumps(response, ensure_ascii=False).encode())
  File "/Library/Developer/CommandLineTools/Library/Frameworks/Python3.framework/Versions/3.9/lib/python3.9/socketserver.py", line 826, in write
    self._sock.sendall(b)
BrokenPipeError: [Errno 32] Broken pipe

During handling of the above exception, another exception occurred:

Traceback (most recent call last):
  File "/Library/Developer/CommandLineTools/Library/Frameworks/Python3.framework/Versions/3.9/lib/python3.9/socketserver.py", line 316, in _handle_request_noblock
    self.process_request(request, client_address)
  File "/Library/Developer/CommandLineTools/Library/Frameworks/Python3.framework/Versions/3.9/lib/python3.9/socketserver.py", line 347, in process_request
    self.finish_request(request, client_address)
  File "/Library/Developer/CommandLineTools/Library/Frameworks/Python3.framework/Versions/3.9/lib/python3.9/socketserver.py", line 360, in finish_request
    self.RequestHandlerClass(request, client_address, self)
  File "/Library/Developer/CommandLineTools/Library/Frameworks/Python3.framework/Versions/3.9/lib/python3.9/socketserver.py", line 747, in __init__
    self.handle()
  File "/Library/Developer/CommandLineTools/Library/Frameworks/Python3.framework/Versions/3.9/lib/python3.9/http/server.py", line 434, in handle
    self.handle_one_request()
  File "/Library/Developer/CommandLineTools/Library/Frameworks/Python3.framework/Versions/3.9/lib/python3.9/http/server.py", line 422, in handle_one_request
    method()
  File "/Users/facundorios/Documents/Facundo/Programacion/Proyectos/Proyecto Messi/proxy_server.py", line 23, in do_GET
    self.update_stats()
  File "/Users/facundorios/Documents/Facundo/Programacion/Proyectos/Proyecto Messi/proxy_server.py", line 162, in update_stats
    self.send_error(500, f"Error en actualización: {str(e)}")
  File "/Library/Developer/CommandLineTools/Library/Frameworks/Python3.framework/Versions/3.9/lib/python3.9/http/server.py", line 486, in send_error
    self.end_headers()
  File "/Library/Developer/CommandLineTools/Library/Frameworks/Python3.framework/Versions/3.9/lib/python3.9/http/server.py", line 536, in end_headers
    self.flush_headers()
  File "/Library/Developer/CommandLineTools/Library/Frameworks/Python3.framework/Versions/3.9/lib/python3.9/http/server.py", line 540, in flush_headers
    self.wfile.write(b"".join(self._headers_buffer))
  File "/Library/Developer/CommandLineTools/Library/Frameworks/Python3.framework/Versions/3.9/lib/python3.9/socketserver.py", line 826, in write
    self._sock.sendall(b)
BrokenPipeError: [Errno 32] Broken pipe
----------------------------------------
